<?xml version="1.0"?> 
<robot name="jax" 
xmlns:xacro="http://www.ros.org/wiki/xacro">

  <!-- World link -->
  <link name="world"/>

  <!-- Fixed joint to base -->
  <joint name="world_to_base" type="fixed">
    <parent link="world"/>
    <child link="base_link"/>
    <origin xyz="0 0 0" rpy="0 0 0"/>
  </joint>



  <!-- Materials -->
<material name="black">
    <color rgba="0.1 0.1 0.1 1.0"/> 
  </material>

<!-- Base link -->
<link name="base_link">
    <visual>
      <geometry> 
          <box size="0.25 0.15 0.05"/>
      </geometry>
      <material name="black"/>
    </visual>

<collision>
  <geometry>
    <box size="0.25 0.15 0.05"/>
  </geometry> 
</collision>

    <inertial> 
      <mass value="3.0"/>
      <origin xyz="0 0 0"/>
      <inertia
        ixx="0.02" ixy="0.0" ixz="0.0" 
        iyy="0.04" iyz="0.0"
        izz="0.05"/>
    </inertial> 
</link>

<!-- ============================= -->
<!-- Front Left Hip -->
<!-- ============================= -->

<link 
  name="front_left_hip_link">
    <visual>
      <geometry>
        <cylinder radius="0.015" length="0.08"/> 
      </geometry> 
      <material name="black"/>
    </visual> 
    
<collision>
      <geometry> 
        <cylinder radius="0.015" length="0.08"/>
        </geometry> 
</collision> 

<inertial>
<mass value="0.2"/>
<origin xyz="0 0 0"/>
<inertia
      ixx="0.0001" ixy="0.0" ixz="0.0"
      iyy="0.0001" iyz="0.0" 
      izz="0.0001"/> 
</inertial>
</link>

<joint name="front_left_hip_joint" 
type="revolute"> 
  <parent link="base_link"/> 
  <child link="front_left_hip_link"/>

<!--Position relative to base --> 
<origin xyz="0.10 0.075 0.0" rpy="0 0 0"/> 

<!-- Hip rotates forward/back --> 
<axis xyz="0 1 0"/> 

<limit
      lower="-1.57" 
      upper="1.57" 
      effort="5.0" 
      velocity="2.0"/>
  </joint>

</robot>
