<?xml version="1.0"?> 
<robot name="jax" 
xmlns:xacro="http://www.ros.org/wiki/xacro">

  <!-- World link -->
  <link name="world"/>

  <!-- Fixed joint to base -->
  <joint name="world_to_base" type="fixed">
    <parent link="world"/>
    <child link="base_link"/>
    <origin xyz="0 0 0.23" rpy="0 0 0"/>
  </joint>



  <!-- Materials -->
<material name="black">
    <color rgba="0.1 0.1 0.1 1.0"/> 
  </material>

<material name="white">
  <color rgba="1 1 1 1"/>
</material>

<material name="debug">
  <color rgba="1 0 0 0.4"/>
  
</material>


<!-- Base link -->
<link name="base_link">

   <visual>
    <origin xyz="0 0 0" rpy="0 0 0"/>
      <geometry>
        <mesh filename="package://jax_description/meshes/base_link.stl"
          scale=".001 .001 .001"/>
     </geometry>
    <material name="white"/>
    </visual>

  <collision>
  <origin xyz="0 0 0" rpy="0 0 0"/>
  <geometry>
    <box size="0.26 0.14 0.06"/>
  </geometry>
  </collision>

  <inertial> 
    <mass value="3.0"/>
    <origin xyz="0 0 0"/>
    <inertia
      ixx="0.02" ixy="0.0" ixz="0.0" 
      iyy="0.04" iyz="0.0"
      izz="0.05"/>
  </inertial> 

</link>

  

  <!-- FRONT RIGHT LEG -->

  <link name="front_right_hip">
    <visual>
      <origin xyz="0 -0.035 0.01" rpy="0 0 0"/> 
      <geometry>
        <mesh filename="package://jax_description/meshes/right_hip.stl"
          scale=".001 .001 .001"/>
      </geometry>
      <material name="black"/>
    </visual>

     <collision>
      <origin xyz="0 -0.02 0"/>
     <geometry>
      <sphere radius="0.025"/>
     </geometry>
     </collision>

    <inertial>
      <mass value="0.15"/>
      <origin xyz="0 -0.02 0"/>
      <inertia
      ixx="0.0002" ixy="0" ixz="0"
      iyy="0.0002" iyz="0"
      izz="0.0002"/>
    </inertial>

  </link>


<joint name="front_right_hip_joint" type="revolute">
  <parent link="base_link"/>
  <child link="front_right_hip"/>
  <origin xyz="0.11 -0.06 -0.01"/>
  <axis xyz="1 0 0"/>
  <limit lower="-0.6" upper="0.6" effort="2.0" velocity="1.5"/>
  <dynamics damping="0.5" friction="0.0"/>
</joint>


<link name="front_right_thigh">
  <visual>
    <origin xyz="0 -.038 0" rpy="0 0 0"/>
    <geometry>
          <mesh filename="package://jax_description/meshes/right_thigh.stl"
          scale=".001 .001 .001"/>
    </geometry>
    <material name="white"/>
  </visual>

  <collision>
    <origin xyz="0 -.039 -0.065"/>
    <geometry>
      <cylinder radius="0.012" length="0.15"/>
    </geometry>
  </collision>

  <inertial>
    <mass value="0.35"/>
    <origin xyz="0 -0.39 -0.065"/>
    <inertia
      ixx="0.001" ixy="0" ixz="0"
      iyy="0.001" iyz="0"
      izz="0.0003"/>
  </inertial>

</link>


  <joint name="front_right_thigh_joint" type="revolute">
    <parent link="front_right_hip"/>
    <child link="front_right_thigh"/>
    <origin xyz="0 0 0.01"/>
    <axis xyz="0 -1 0"/>
    <limit lower="-1.2" upper="1.2" effort="3.0" velocity="2.0"/>
    <dynamics damping="0.7" friction="0.0"/>
  </joint>

  <link name="front_right_calf">
    <visual>
      <origin xyz="0 -0.048 0" rpy="0 0 0"/>
      <geometry>
        <mesh filename="package://jax_description/meshes/right_calf.stl"
          scale=".001 .001 .001"/>
      </geometry>
      <material name="black"/>
    </visual> 

    <collision>
      <origin xyz="0.05 -0.043 -0.045" rpy="0 -0.85 0"/>
      <geometry>
        <cylinder radius="0.012" length="0.13"/>
      </geometry>
    </collision>

    <inertial>
      <mass value="0.25"/>
      <origin xyz="0.05 -0.043 -0.045" rpy="0 -0.85 0"/>
      <inertia
      ixx="0.0007" ixy="0" ixz="0"
      iyy="0.0007" iyz="0"
      izz="0.0002"/>
    </inertial>


  </link>

  <joint name="front_right_knee_joint" type="revolute">
  <parent link="front_right_thigh"/>
  <child link="front_right_calf"/>
  <origin xyz="0 0 -0.13"/>
  <axis xyz="0 -1 0"/>
  <limit lower="0" upper="1.4" effort="4.0" velocity="2.5"/>
  <dynamics damping="0.9" friction="0.0"/>
</joint>

<link name="front_right_foot">

  <visual>
    <origin xyz="0 0 0" rpy="0 0 0"/>
    <geometry>
      <mesh filename="package://jax_description/meshes/foot.stl"
            scale=".001 .001 .001"/>
    </geometry>
    <material name="black">
    </material>
  </visual>

  <collision>
    <origin xyz="0 0 0.005"/>
    <geometry>
      <sphere radius="0.010"/>
    </geometry>
  </collision>

  <inertial>
    <mass value="0.08"/>
    <origin xyz="0 0 0.005"/>
    <inertia
      ixx="0.00005" ixy="0" ixz="0"
      iyy="0.00005" iyz="0"
      izz="0.00005"/>
  </inertial>



</link>

<joint name="front_right_ankle_joint" type="fixed">
  <parent link="front_right_calf"/>
  <child link="front_right_foot"/>
  <origin xyz="0.095 -0.044 -0.1" rpy="0 0 0"/>
</joint>

<gazebo reference="front_right_foot">
  <mu1>1.2</mu1>
  <mu2>1.2</mu2>
  <kp>100000</kp>
  <kd>100</kd>
</gazebo>


<!-- FRONT LEFT LEG -->

<link name="front_left_hip">
  <visual>
    <origin xyz="0 0.035 0.01"/>
    <geometry>
      <mesh filename="package://jax_description/meshes/left_hip.stl"
            scale=".001 .001 .001"/>
    </geometry>
    <material name="black"/>
  </visual>

  <collision>
    <origin xyz="0 0.02 0"/>
    <geometry>
      <sphere radius="0.025"/>
    </geometry>
  </collision>

  <inertial>
    <mass value="0.15"/>
    <origin xyz="0 0.02 0"/>
    <inertia ixx="0.0002" ixy="0" ixz="0"
             iyy="0.0002" iyz="0"
             izz="0.0002"/>
  </inertial>
</link>

<joint name="front_left_hip_joint" type="revolute">
  <parent link="base_link"/>
  <child link="front_left_hip"/>
  <origin xyz="0.11 0.06 -0.01"/>
  <axis xyz="1 0 0"/>
  <limit lower="-0.6" upper="0.6" effort="2.0" velocity="1.5"/>
  <dynamics damping="0.5" friction="0.0"/>
</joint>

<link name="front_left_thigh">
  <visual>
    <origin xyz="0 0.038 0"/>
    <geometry>
      <mesh filename="package://jax_description/meshes/left_thigh.stl"
            scale=".001 .001 .001"/>
    </geometry>
    <material name="white"/>
  </visual>

  <collision>
    <origin xyz="0 0.039 -0.065"/>
    <geometry>
      <cylinder radius="0.012" length="0.15"/>
    </geometry>
  </collision>

  <inertial>
    <mass value="0.35"/>
    <origin xyz="0 0.039 -0.065"/>
    <inertia ixx="0.001" ixy="0" ixz="0"
             iyy="0.001" iyz="0"
             izz="0.0003"/>
  </inertial>
</link>

<joint name="front_left_thigh_joint" type="revolute">
  <parent link="front_left_hip"/>
  <child link="front_left_thigh"/>
  <origin xyz="0 0 0.01"/>
  <axis xyz="0 -1 0"/>
  <limit lower="-1.2" upper="1.2" effort="3.0" velocity="2.0"/>
  <dynamics damping="0.7" friction="0.0"/>
</joint>

<link name="front_left_calf">
  <visual>
    <origin xyz="0 0.048 0"/>
    <geometry>
      <mesh filename="package://jax_description/meshes/left_calf.stl"
            scale=".001 .001 .001"/>
    </geometry>
    <material name="black"/>
  </visual>

  <collision>
    <origin xyz="0.05 0.043 -0.045" rpy="0 -0.85 0"/>
    <geometry>
      <cylinder radius="0.012" length="0.13"/>
    </geometry>
  </collision>

  <inertial>
    <mass value="0.25"/>
    <origin xyz="0.05 0.043 -0.045" rpy="0 -0.85 0"/>
    <inertia ixx="0.0007" ixy="0" ixz="0"
             iyy="0.0007" iyz="0"
             izz="0.0002"/>
  </inertial>
</link>

<joint name="front_left_knee_joint" type="revolute">
  <parent link="front_left_thigh"/>
  <child link="front_left_calf"/>
  <origin xyz="0 0 -0.13"/>
  <axis xyz="0 -1 0"/>
  <limit lower="0" upper="1.4" effort="4.0" velocity="2.5"/>
  <dynamics damping="0.9" friction="0.0"/>
</joint>

<link name="front_left_foot">
  <visual>
    <geometry>
      <mesh filename="package://jax_description/meshes/foot.stl"
            scale=".001 .001 .001"/>
    </geometry>
    <material name="black"/>
  </visual>

  <collision>
    <origin xyz="0 0 0.005"/>
    <geometry>
      <sphere radius="0.010"/>
    </geometry>
  </collision>

  <inertial>
    <mass value="0.08"/>
    <origin xyz="0 0 0.005"/>
    <inertia ixx="0.00005" ixy="0" ixz="0"
             iyy="0.00005" iyz="0"
             izz="0.00005"/>
  </inertial>
</link>

<joint name="front_left_ankle_joint" type="fixed">
  <parent link="front_left_calf"/>
  <child link="front_left_foot"/>
  <origin xyz="0.095 0.044 -0.1" rpy="0 0 0"/>
</joint>

<gazebo reference="front_left_foot">
  <mu1>1.2</mu1>
  <mu2>1.2</mu2>
  <kp>100000</kp>
  <kd>100</kd>
</gazebo>

<!-- REAR RIGHT LEG -->

<link name="rear_right_hip">
  <visual>
    <origin xyz="0 -0.035 0.01"/>
    <geometry>
      <mesh filename="package://jax_description/meshes/right_hip.stl"
            scale=".001 .001 .001"/>
    </geometry>
    <material name="black"/>
  </visual>

  <collision>
    <origin xyz="0 -0.02 0"/>
    <geometry>
      <sphere radius="0.025"/>
    </geometry>
  </collision>

  <inertial>
    <mass value="0.15"/>
    <origin xyz="0 -0.02 0"/>
    <inertia ixx="0.0002" ixy="0" ixz="0"
             iyy="0.0002" iyz="0"
             izz="0.0002"/>
  </inertial>
</link>

<joint name="rear_right_hip_joint" type="revolute">
  <parent link="base_link"/>
  <child link="rear_right_hip"/>
  <origin xyz="-0.11 -0.06 -0.01"/>
  <axis xyz="1 0 0"/>
  <limit lower="-0.6" upper="0.6" effort="2.0" velocity="1.5"/>
  <dynamics damping="0.5" friction="0.0"/>
</joint>

<link name="rear_right_thigh">
  <visual>
    <origin xyz="0 -0.038 0"/>
    <geometry>
      <mesh filename="package://jax_description/meshes/right_thigh.stl"
            scale=".001 .001 .001"/>
    </geometry>
    <material name="white"/>
  </visual>

  <collision>
    <origin xyz="0 -0.039 -0.065"/>
    <geometry>
      <cylinder radius="0.012" length="0.15"/>
    </geometry>
  </collision>

  <inertial>
    <mass value="0.35"/>
    <origin xyz="0 -0.039 -0.065"/>
    <inertia ixx="0.001" ixy="0" ixz="0"
             iyy="0.001" iyz="0"
             izz="0.0003"/>
  </inertial>
</link>

<joint name="rear_right_thigh_joint" type="revolute">
  <parent link="rear_right_hip"/>
  <child link="rear_right_thigh"/>
  <origin xyz="0 0 0.01"/>
  <axis xyz="0 -1 0"/>
  <limit lower="-1.2" upper="1.2" effort="3.0" velocity="2.0"/>
  <dynamics damping="0.7" friction="0.0"/>
</joint>

<link name="rear_right_calf">
  <visual>
    <origin xyz="0 -0.048 0"/>
    <geometry>
      <mesh filename="package://jax_description/meshes/right_calf.stl"
            scale=".001 .001 .001"/>
    </geometry>
    <material name="black"/>
  </visual>

  <collision>
    <origin xyz="0.05 -0.043 -0.045" rpy="0 -0.85 0"/>
    <geometry>
      <cylinder radius="0.012" length="0.13"/>
    </geometry>
  </collision>

  <inertial>
    <mass value="0.25"/>
    <origin xyz="0.05 -0.043 -0.045" rpy="0 -0.85 0"/>
    <inertia ixx="0.0007" ixy="0" ixz="0"
             iyy="0.0007" iyz="0"
             izz="0.0002"/>
  </inertial>
</link>

<joint name="rear_right_knee_joint" type="revolute">
  <parent link="rear_right_thigh"/>
  <child link="rear_right_calf"/>
  <origin xyz="0 0 -0.13"/>
  <axis xyz="0 -1 0"/>
  <limit lower="0" upper="1.4" effort="4.0" velocity="2.5"/>
  <dynamics damping="0.9" friction="0.0"/>
</joint>

<link name="rear_right_foot">
  <visual>
    <origin xyz="0 0 0" rpy="0 0 0"/>
    <geometry>
      <mesh filename="package://jax_description/meshes/foot.stl"
            scale=".001 .001 .001"/>
    </geometry>
    <material name="black"/>
  </visual>

  <collision>
    <origin xyz="0 0 0.005"/>
    <geometry>
      <sphere radius="0.010"/>
    </geometry>
  </collision>

  <inertial>
    <mass value="0.08"/>
    <origin xyz="0 0 0.005"/>
    <inertia
      ixx="0.00005" ixy="0" ixz="0"
      iyy="0.00005" iyz="0"
      izz="0.00005"/>
  </inertial>
</link>

<joint name="rear_right_ankle_joint" type="fixed">
  <parent link="rear_right_calf"/>
  <child link="rear_right_foot"/>
  <origin xyz="0.095 -0.044 -0.1" rpy="0 0 0"/>
</joint>

<gazebo reference="rear_right_foot">
  <mu1>1.2</mu1>
  <mu2>1.2</mu2>
  <kp>100000</kp>
  <kd>100</kd>
</gazebo>


<!-- REAR LEFT LEG -->

<link name="rear_left_hip">
  <visual>
    <origin xyz="0 0.035 0.01"/>
    <geometry>
      <mesh filename="package://jax_description/meshes/left_hip.stl"
            scale=".001 .001 .001"/>
    </geometry>
    <material name="black"/>
  </visual>

  <collision>
    <origin xyz="0 0.02 0"/>
    <geometry>
      <sphere radius="0.025"/>
    </geometry>
  </collision>

  <inertial>
    <mass value="0.15"/>
    <origin xyz="0 0.02 0"/>
    <inertia
      ixx="0.0002" ixy="0" ixz="0"
      iyy="0.0002" iyz="0"
      izz="0.0002"/>
  </inertial>
</link>

<joint name="rear_left_hip_joint" type="revolute">
  <parent link="base_link"/>
  <child link="rear_left_hip"/>
  <origin xyz="-0.11 0.06 -0.01"/>
  <axis xyz="1 0 0"/>
  <limit lower="-0.6" upper="0.6" effort="2.0" velocity="1.5"/>
  <dynamics damping="0.5" friction="0.0"/>
</joint>

<link name="rear_left_thigh">
  <visual>
    <origin xyz="0 0.038 0"/>
    <geometry>
      <mesh filename="package://jax_description/meshes/left_thigh.stl"
            scale=".001 .001 .001"/>
    </geometry>
    <material name="white"/>
  </visual>

  <collision>
    <origin xyz="0 0.039 -0.065"/>
    <geometry>
      <cylinder radius="0.012" length="0.15"/>
    </geometry>
  </collision>

  <inertial>
    <mass value="0.35"/>
    <origin xyz="0 0.039 -0.065"/>
    <inertia
      ixx="0.001" ixy="0" ixz="0"
      iyy="0.001" iyz="0"
      izz="0.0003"/>
  </inertial>
</link>

<joint name="rear_left_thigh_joint" type="revolute">
  <parent link="rear_left_hip"/>
  <child link="rear_left_thigh"/>
  <origin xyz="0 0 0.01"/>
  <axis xyz="0 -1 0"/>
  <limit lower="-1.2" upper="1.2" effort="3.0" velocity="2.0"/>
  <dynamics damping="0.7" friction="0.0"/>
</joint>

<link name="rear_left_calf">
  <visual>
    <origin xyz="0 0.048 0"/>
    <geometry>
      <mesh filename="package://jax_description/meshes/left_calf.stl"
            scale=".001 .001 .001"/>
    </geometry>
    <material name="black"/>
  </visual>

  <collision>
    <origin xyz="0.05 0.043 -0.045" rpy="0 -0.85 0"/>
    <geometry>
      <cylinder radius="0.012" length="0.13"/>
    </geometry>
  </collision>

  <inertial>
    <mass value="0.25"/>
    <origin xyz="0.05 0.043 -0.045" rpy="0 -0.85 0"/>
    <inertia
      ixx="0.0007" ixy="0" ixz="0"
      iyy="0.0007" iyz="0"
      izz="0.0002"/>
  </inertial>
</link>

<joint name="rear_left_knee_joint" type="revolute">
  <parent link="rear_left_thigh"/>
  <child link="rear_left_calf"/>
  <origin xyz="0 0 -0.13"/>
  <axis xyz="0 -1 0"/>
  <limit lower="0" upper="1.4" effort="4.0" velocity="2.5"/>
  <dynamics damping="0.9" friction="0.0"/>
</joint>

<link name="rear_left_foot">
  <visual>
    <geometry>
      <mesh filename="package://jax_description/meshes/foot.stl"
            scale=".001 .001 .001"/>
    </geometry>
    <material name="black"/>
  </visual>

  <collision>
    <origin xyz="0 0 0.005"/>
    <geometry>
      <sphere radius="0.010"/>
    </geometry>
  </collision>

  <inertial>
    <mass value="0.08"/>
    <origin xyz="0 0 0.005"/>
    <inertia
      ixx="0.00005" ixy="0" ixz="0"
      iyy="0.00005" iyz="0"
      izz="0.00005"/>
  </inertial>
</link>

<joint name="rear_left_ankle_joint" type="fixed">
  <parent link="rear_left_calf"/>
  <child link="rear_left_foot"/>
  <origin xyz="0.095 0.044 -0.1" rpy="0 0 0"/>
</joint>

<gazebo reference="rear_left_foot">
  <mu1>1.2</mu1>
  <mu2>1.2</mu2>
  <kp>100000</kp>
  <kd>100</kd>
</gazebo>

</robot>
