<?xml version="1.0"?> 
<robot name="jax" 
xmlns:xacro="http://www.ros.org/wiki/xacro">

  <!-- World link -->
  <link name="world"/>

  <!-- Fixed joint to base -->
  <joint name="world_to_base" type="fixed">
    <parent link="world"/>
    <child link="base_link"/>
    <origin xyz="0 0 0" rpy="0 0 0"/>
  </joint>



  <!-- Materials -->
<material name="black">
    <color rgba="0.1 0.1 0.1 1.0"/> 
  </material>

<material name="white">
  <color rgba="1 1 1 1"/>
</material>

<material name="debug">
  <color rgba="1 0 0 0.4"/>
  
</material>


<!-- Base link -->
<link name="base_link">

   <visual>
  <origin xyz="0 0 0" rpy="0 0 0"/>
  <geometry>
    <mesh filename="package://jax_description/meshes/base_link.stl"
          scale=".1 .1 .1"/>
  </geometry>
  <material name="white"/>
</visual>

<collision>
  <origin xyz="0 0 0" rpy="0 0 0"/>
  <geometry>
    <mesh filename="package://jax_description/meshes/base_collision.stl"
          scale=".001 .001 .001"/>
  </geometry>
</collision>

  <inertial> 
    <mass value="3.0"/>
    <origin xyz="0 0 0"/>
    <inertia
      ixx="0.02" ixy="0.0" ixz="0.0" 
      iyy="0.04" iyz="0.0"
      izz="0.05"/>
  </inertial> 

</link>

  

  <!-- FRONT RIGHT LEG -->

  <link name="front_right_hip">
    <visual>
      <origin xyz="0 -0.035 0.01" rpy="0 0 0"/> 
      <geometry>
        <mesh filename="package://jax_description/meshes/right_hip.stl"
          scale=".001 .001 .001"/>
      </geometry>
      <material name="black"/>
    </visual>
  </link>


<joint name="front_right_hip_joint" type="revolute">
  <parent link="base_link"/>
  <child link="front_right_hip"/>
  <origin xyz="0.11 -0.06 -0.01"/>
  <axis xyz="1 0 0"/>
  <limit lower="-0.6" upper="0.6" effort="1.0" velocity="1.0"/>
</joint>


<link name="front_right_thigh">
  <visual>
    <origin xyz="0 -.038 0" rpy="0 0 0"/>
    <geometry>
          <mesh filename="package://jax_description/meshes/right_thigh.stl"
          scale=".001 .001 .001"/>
  </geometry>
    <material name="white"/>
  </visual>
</link>



  <joint name="front_right_thigh_joint" type="revolute">
    <parent link="front_right_hip"/>
    <child link="front_right_thigh"/>
    <origin xyz="0 0 0.01"/>
    <axis xyz="0 -1 0"/>
    <limit lower="-1.2" upper="1.2" effort="1.0" velocity="1.0"/>
  </joint>

  <link name="front_right_calf">
    <visual>
      <origin xyz="0 -0.048 0" rpy="0 0 0"/>
      <geometry>
        <mesh filename="package://jax_description/meshes/right_calf.stl"
          scale=".001 .001 .001"/>
      </geometry>
      <material name="black"/>
    </visual> 
   </link>

  <joint name="front_right_knee_joint" type="revolute">
  <parent link="front_right_thigh"/>
  <child link="front_right_calf"/>
  <origin xyz="0 0 -0.13"/>
  <axis xyz="0 -1 0"/>
  <limit lower="0" upper="1.4" effort="1.0" velocity="1.0"/>
</joint>

<!-- FRONT LEFT LEG -->

<link name="front_left_hip">
  <visual>
    <origin xyz="0 0.035 0.01" rpy="0 0 0"/> 
    <geometry>
      <mesh filename="package://jax_description/meshes/left_hip.stl"
            scale=".001 .001 .001"/>
    </geometry>
    <material name="black"/>
  </visual>
</link>


<joint name="front_left_hip_joint" type="revolute">
  <parent link="base_link"/>
  <child link="front_left_hip"/>
  <origin xyz="0.11 0.06 -0.01"/>
  <axis xyz="1 0 0"/>
  <limit lower="-0.6" upper="0.6" effort="1.0" velocity="1.0"/>
</joint>

<link name="front_left_thigh">
  <visual>
    <origin xyz="0 0.038 0" rpy="0 0 0"/>
    <geometry>
      <mesh filename="package://jax_description/meshes/left_thigh.stl"
            scale=".001 .001 .001"/>
    </geometry>
    <material name="white"/>
  </visual>
</link>

<joint name="front_left_thigh_joint" type="revolute">
  <parent link="front_left_hip"/>
  <child link="front_left_thigh"/>
  <origin xyz="0 0 0.01"/>
  <axis xyz="0 -1 0"/>
  <limit lower="-1.2" upper="1.2" effort="1.0" velocity="1.0"/>
</joint>

<link name="front_left_calf">
  <visual>
    <origin xyz="0 0.048 0" rpy="0 0 0"/>
    <geometry>
      <mesh filename="package://jax_description/meshes/left_calf.stl"
            scale=".001 .001 .001"/>
    </geometry>
    <material name="black"/>
  </visual>
</link>

<joint name="front_left_knee_joint" type="revolute">
  <parent link="front_left_thigh"/>
  <child link="front_left_calf"/>
  <origin xyz="0 0 -0.13"/>
  <axis xyz="0 -1 0"/>
  <limit lower="0" upper="1.4" effort="1.0" velocity="1.0"/>
</joint>


<!-- REAR RIGHT LEG -->

<link name="rear_right_hip">
  <visual>
    <origin xyz="0 -0.035 0.01" rpy="0 0 0"/> 
    <geometry>
      <mesh filename="package://jax_description/meshes/right_hip.stl"
            scale=".001 .001 .001"/>
    </geometry>
    <material name="black"/>
  </visual>
</link>

<joint name="rear_right_hip_joint" type="revolute">
  <parent link="base_link"/>
  <child link="rear_right_hip"/>
  <origin xyz="-0.11 -0.06 -0.01"/>
  <axis xyz="1 0 0"/>
  <limit lower="-0.6" upper="0.6" effort="1.0" velocity="1.0"/>
</joint>

<link name="rear_right_thigh">
  <visual>
    <origin xyz="0 -0.038 0" rpy="0 0 0"/>
    <geometry>
      <mesh filename="package://jax_description/meshes/right_thigh.stl"
            scale=".001 .001 .001"/>
    </geometry>
    <material name="white"/>
  </visual>
</link>

<joint name="rear_right_thigh_joint" type="revolute">
  <parent link="rear_right_hip"/>
  <child link="rear_right_thigh"/>
  <origin xyz="0 0 0.01"/>
  <axis xyz="0 -1 0"/>
  <limit lower="-1.2" upper="1.2" effort="1.0" velocity="1.0"/>
</joint>

<link name="rear_right_calf">
  <visual>
    <origin xyz="0 -0.048 0" rpy="0 0 0"/>
    <geometry>
      <mesh filename="package://jax_description/meshes/right_calf.stl"
            scale=".001 .001 .001"/>
    </geometry>
    <material name="black"/>
  </visual>
</link>

<joint name="rear_right_knee_joint" type="revolute">
  <parent link="rear_right_thigh"/>
  <child link="rear_right_calf"/>
  <origin xyz="0 0 -0.13"/>
  <axis xyz="0 -1 0"/>
  <limit lower="0" upper="1.4" effort="1.0" velocity="1.0"/>
</joint>


<!-- REAR LEFT LEG -->

<link name="rear_left_hip">
  <visual>
    <origin xyz="0 0.035 0.01" rpy="0 0 0"/> 
    <geometry>
      <mesh filename="package://jax_description/meshes/left_hip.stl"
            scale=".001 .001 .001"/>
    </geometry>
    <material name="black"/>
  </visual>
</link>

<joint name="rear_left_hip_joint" type="revolute">
  <parent link="base_link"/>
  <child link="rear_left_hip"/>
  <origin xyz="-0.11 0.06 -0.01"/>
  <axis xyz="1 0 0"/>
  <limit lower="-0.6" upper="0.6" effort="1.0" velocity="1.0"/>
</joint>

<link name="rear_left_thigh">
  <visual>
    <origin xyz="0 0.038 0" rpy="0 0 0"/>
    <geometry>
      <mesh filename="package://jax_description/meshes/left_thigh.stl"
            scale=".001 .001 .001"/>
    </geometry>
    <material name="white"/>
  </visual>
</link>

<joint name="rear_left_thigh_joint" type="revolute">
  <parent link="rear_left_hip"/>
  <child link="rear_left_thigh"/>
  <origin xyz="0 0 0.01"/>
  <axis xyz="0 -1 0"/>
  <limit lower="-1.2" upper="1.2" effort="1.0" velocity="1.0"/>
</joint>

<link name="rear_left_calf">
  <visual>
    <origin xyz="0 0.048 0" rpy="0 0 0"/>
    <geometry>
      <mesh filename="package://jax_description/meshes/left_calf.stl"
            scale=".001 .001 .001"/>
    </geometry>
    <material name="black"/>
  </visual>
</link>

<joint name="rear_left_knee_joint" type="revolute">
  <parent link="rear_left_thigh"/>
  <child link="rear_left_calf"/>
  <origin xyz="0 0 -0.13"/>
  <axis xyz="0 -1 0"/>
  <limit lower="0" upper="1.4" effort="1.0" velocity="1.0"/>
</joint>


</robot>
